Exception on /upload_file [GET]
Traceback (most recent call last):
  File "c:\users\joseph\appdata\local\programs\python\python38\lib\site-packages\flask\app.py", line 1523, in full_dispatch_request
    rv = self.dispatch_request()
  File "c:\users\joseph\appdata\local\programs\python\python38\lib\site-packages\flask\app.py", line 1509, in dispatch_request
    return self.ensure_sync(self.view_functions[rule.endpoint])(**req.view_args)
TypeError: upload_file() missing 1 required positional argument: 'file'

During handling of the above exception, another exception occurred:

Traceback (most recent call last):
  File "c:\users\joseph\appdata\local\programs\python\python38\lib\site-packages\flask\wrappers.py", line 128, in on_json_loading_failed
    return super().on_json_loading_failed(e)
  File "c:\users\joseph\appdata\local\programs\python\python38\lib\site-packages\werkzeug\wrappers\request.py", line 611, in on_json_loading_failed
    raise BadRequest(
werkzeug.exceptions.BadRequest: 400 Bad Request: Did not attempt to load JSON data because the request Content-Type was not 'application/json'.

The above exception was the direct cause of the following exception:

Traceback (most recent call last):
  File "c:\users\joseph\appdata\local\programs\python\python38\lib\site-packages\flask\app.py", line 2077, in wsgi_app
    response = self.full_dispatch_request()
  File "c:\users\joseph\appdata\local\programs\python\python38\lib\site-packages\flask\app.py", line 1525, in full_dispatch_request
    rv = self.handle_user_exception(e)
  File "c:\users\joseph\appdata\local\programs\python\python38\lib\site-packages\flask\app.py", line 1391, in handle_user_exception
    return self.ensure_sync(handler)(e)
  File "D:\EXL\Hackathon\app.py", line 84, in exceptions
    request.get_json(),
  File "c:\users\joseph\appdata\local\programs\python\python38\lib\site-packages\werkzeug\wrappers\request.py", line 571, in get_json
    return self.on_json_loading_failed(None)
  File "c:\users\joseph\appdata\local\programs\python\python38\lib\site-packages\flask\wrappers.py", line 133, in on_json_loading_failed
    raise BadRequest() from e
werkzeug.exceptions.BadRequest: 400 Bad Request: The browser (or proxy) sent a request that this server could not understand.
Exception on /upload_file [POST]
Traceback (most recent call last):
  File "c:\users\joseph\appdata\local\programs\python\python38\lib\site-packages\flask\app.py", line 1523, in full_dispatch_request
    rv = self.dispatch_request()
  File "c:\users\joseph\appdata\local\programs\python\python38\lib\site-packages\flask\app.py", line 1509, in dispatch_request
    return self.ensure_sync(self.view_functions[rule.endpoint])(**req.view_args)
TypeError: upload_file() missing 1 required positional argument: 'file'

During handling of the above exception, another exception occurred:

Traceback (most recent call last):
  File "c:\users\joseph\appdata\local\programs\python\python38\lib\site-packages\flask\wrappers.py", line 128, in on_json_loading_failed
    return super().on_json_loading_failed(e)
  File "c:\users\joseph\appdata\local\programs\python\python38\lib\site-packages\werkzeug\wrappers\request.py", line 611, in on_json_loading_failed
    raise BadRequest(
werkzeug.exceptions.BadRequest: 400 Bad Request: Did not attempt to load JSON data because the request Content-Type was not 'application/json'.

The above exception was the direct cause of the following exception:

Traceback (most recent call last):
  File "c:\users\joseph\appdata\local\programs\python\python38\lib\site-packages\flask\app.py", line 2077, in wsgi_app
    response = self.full_dispatch_request()
  File "c:\users\joseph\appdata\local\programs\python\python38\lib\site-packages\flask\app.py", line 1525, in full_dispatch_request
    rv = self.handle_user_exception(e)
  File "c:\users\joseph\appdata\local\programs\python\python38\lib\site-packages\flask\app.py", line 1391, in handle_user_exception
    return self.ensure_sync(handler)(e)
  File "D:\EXL\Hackathon\app.py", line 84, in exceptions
    ts = strftime('[%Y-%b-%d %H:%M]')
  File "c:\users\joseph\appdata\local\programs\python\python38\lib\site-packages\werkzeug\wrappers\request.py", line 571, in get_json
    return self.on_json_loading_failed(None)
  File "c:\users\joseph\appdata\local\programs\python\python38\lib\site-packages\flask\wrappers.py", line 133, in on_json_loading_failed
    raise BadRequest() from e
werkzeug.exceptions.BadRequest: 400 Bad Request: The browser (or proxy) sent a request that this server could not understand.
